---
title: discord.py 再起動に関するメモ
tags:  discord.py
categories:  プログラミング
author: @1ntegrale9
status: public
created_at: 2019-06-25 01:23:10 +0900
updated_at: 2019-06-25 01:23:10 +0900
published_at: 2019-06-25 01:23:10 +0900
---
某所にて、再起動するコマンドが動かないという質問があった。
このようなコード。

```python
import asyncio
import discord
import os
import sys
import traceback

client = discord.Client()
Token = os.environ['DISCORD_BOT_TOKEN']

@client.event
async def on_ready():
    print('login')

@client.event
async def on_message(message):
    if message.content == '!r':
        await client.logout()
        os.execv(sys.executable,[sys.executable, os.path.join(sys.path[0], __file__)] + sys.argv[1:])

client.run(Token)
```

このまま `!r` を叩くとエラーも吐かずにプロセスが終了する。
printデバッグだと `client.logout()` でループが閉じてる雰囲気までしか
辿り着けないので、traceback を出力してログを追う。

```python
try:
    await client.logout()
except:
    import traceback
    traceback.print_exc()
```

```console
Traceback (most recent call last):
  File "sample.py", line 20, in on_message
    await client.logout()
  File "/Library/Frameworks/Python.framework/Versions/3.7/lib/python3.7/site-packages/discord/client.py", line 390, in logout
    await self.close()
  File "/Library/Frameworks/Python.framework/Versions/3.7/lib/python3.7/site-packages/discord/client.py", line 486, in close
    await self.ws.close()
  File "/Library/Frameworks/Python.framework/Versions/3.7/lib/python3.7/site-packages/discord/gateway.py", line 538, in close
    await super().close(code, reason)
  File "/Library/Frameworks/Python.framework/Versions/3.7/lib/python3.7/site-packages/websockets/protocol.py", line 419, in close
    yield from asyncio.shield(self.close_connection_task)
concurrent.futures._base.CancelledError
```

ここまでログを出せば、discord.py 本体にバグがあることに辿り着ける。

-> on_message の発火時に次のメッセージの受信が始まっているが、
websocket を close するため `syncio.CancelledError` が発生する
